
### 🚀 오류 처리
  
#### 🌟 오류 표현
- Error 프로토콜과 (주로) 열거형을 통해서 오류를 표현한다.
```
enum 오류종류이름: Error {
    case 종류1
    case 종류2
    case 종류3
}
```
- 자판기 동작 오류의 종류를 표현한 VendingMachineError 열거형
```
enum VendingMechineError: Error {
    case invalidInput
    case insufficientFunds(moneyNeeded: Int)
    case outOfStock
}
```
#### 🌟 함수에서 발생한 오류 던지기
```
class VendingMachine {
    let itemPrice: Int = 100
    var itemCount: Int = 5
    var deposited: Int = 0

    // 돈 받기 메서드
    func receiveMoney(_ money: Int) throws {

        // 입력한 돈이 0이하면 오류 던진다.
        guard money > 0 else {
            throw VendingMachineError.invalidInput
        }

        self.deposited += money
        print("\(money)원 받은")
    }

    // 물건 팔기 메서드
    func vend(numberOfItems numberOfItemsToVend: Int) throws -> String {

        //원하는 아이템의 수량이 잘못 입력되었을 때
        guard numberOfItemsToVend > 0 else {
            throw VendingMachineError.invalidInput
        }

        //구매하려는 수량보다 미리 넣어둔 돈이 적을 때
        guard numberOfItemsToVend * itemPrice <= deposited else {
            let moneyNeeded: Int
            moneyNeeded = numberOfItemsToVend * itemPrice - deposited
            throw VendingMachienError.insufficientFunds(moneyNeeded: moneyNeeded)
        }

        //구매하려는 수량보다 요구하는 수량이 많을 때
        guard itemCount >= numberOfItemsToVend else {
            throw VendingMachineError.outOfStock
        }

        // 오류가 없으면 정상처리
        let totalPrice = numberOfItemsToVend * itemPrice

        self.deposited -= totalPrice
        self.itemCount -= numberOfItemsToVend

        return "\(numberOfItemsToVend)개 제공함"
    }
}
```
#### 🌟 오류 처리
- 오류발생의 여지가 있는 throws 함수는 try를 사용하여 호출해야한다.
- try, try?, try!

#### 🌟 do-catch
- 오류발생의 여지가 있는 throws 함수는 do-catch 구문을 활용하여 오류 발생에 대비한다.
```
do {
    try machine.receiveMoney(0)
} catch VendingMachineError.invalidInput {
    print("입력이 잘못되었습니다")
} catch VendingMachineError.insufficientFunds(let moneyNeeded) {
    print("\(moneyNeeded)원이 부족합니다")
} catch VendingMachineError.outOfStock {
    print("수량이 부족합니다")
}

do {
    try machine.receiveMoney(0)
} catch /*(let error)*/ {

    switch error {
    case VendingMechineError.invalidInput:
        print("입력이 잘못되었습니다")
    case VendingMachineError.insufficientFunds(let moneyNeeded):
        print("\(moneyNeeded)원이 부족합니다")
    case VendingMachineError.outOfStock:
        print("수량이 부족합니다")
    default:
        print("알수 없는 오류 \(error)")
    }
}
```
- 간결하게 표현
```
do {
    result = try machine.vend(numberOfItems: 4)
} catch {
    print(error)
}

do {
    result = try machine.vend(numberOfItems: 4)
}
```
#### 🌟 try?
- 별도의 오류처리 결과를 통보받지 않고
- 오류가 발생했으면 결과값을 nil로 돌려받는다.
- 정상동작 후에는 옵셔널 타입으로 정상 반환값을 돌려 받는다.
```
result = try? machine.vend(numberOfItems: 2)
result  // Optional("2개 제공함")
 
result = try? machine.vend(numberOfItems: 2)
result  // 오류가 발생하면 nil
```
#### 🌟 try!
- 오류가 발생하지 않을 것이라는 강력한 확신을 가질 때
- try!를 사용하면 정상동작 후에 바로 결과값을 돌려받는다
- 오류가 발생하면 런타임 오류가 발생하여 애플리케이션 동작이 중지된다.
```
result = try! machine.vend(numberOfItems: 1)  //여기서 만약 정상작동하지 않는다면 중지된다.
result  //1개 제공함


